<mujoco model="t1d1">
    <include file="./common/visual.xml"/>
    <include file="./common/skybox.xml"/>
    <include file="./common/materials.xml"/>
    
    <option timestep="0.01" iterations="50" solver="Newton" tolerance="1e-10" gravity="0 0 0" collision="predefined" viscosity="0.0"/>

    <size njmax="50" nconmax="40" nstack="1500"/>

    <visual>
        <rgba haze=".15 .25 .35 1"/>
    </visual>

    <default>
        <joint type="hinge" pos="0 0 0" axis="0 1 0" limited="false" range="-180 180" damping="0."/>
        <motor ctrllimited="false" ctrlrange="-1 1" gear="1"/>
		<tendon stiffness="0" damping="." width="0.02"/>
		<geom size="0.02" mass="0.6" material="self"/>
		<site size="0.04"/>
    </default>

    <worldbody>
        <light directional="true" diffuse=".8 .8 .8" specular=".2 .2 .2" pos="0 0 5" dir="0 0 -1"/>

        <site name="f2" pos="0 0 0"/>

        <body pos="0 0 0">
            <geom name="lbar1" type="capsule" fromto="0 0 0  -0.8 0 0.6" />
			<site name="lb1e" pos="-0.8 0 0.6"/>
			<joint name="lj1"/>
            <body name="lbar2" pos="-0.8 0 0.6">
                <geom name="lbar2" type="capsule" fromto="0 0 0  0.8 0 0.6"/>
                <joint name="lj2"/>
                <site name="lb2e" pos="0.8 0 0.6"/>
				<body pos="0.8 0 0.6">
					<geom name="lbar3" type="capsule" fromto="0 0 0  -1.5 0 0"/>
					<joint name="lj3"/>
					<site name="lb3e" pos="-1.5 0 0"/>
				</body>
                <body pos="0.8 0 0.6">
					<geom name="lbar4" type="capsule" fromto="0 0 0  -0.8 0 0.6"/>
					<joint name="lj4"/>
					<site name="lb4e" pos="-0.8 0 0.6"/>
                    <body name="lbar5" pos="-0.8 0 0.6">
                        <geom name="lbar5" type="capsule" fromto="0 0 0  0.8 0 0.6"/>
                        <joint name="lj5"/>
                        <site name="lb5e" pos="0.8 0 0.6"/>
                    </body>
				</body>
                <body pos="0.8 0 0.6">
					<geom name="rbar3" type="capsule" fromto="0 0 0  1.5 0 0"/>
					<joint name="rj3"/>
					<site name="rb3e" pos="1.5 0 0"/>
				</body>
            </body>
        </body>
        
        <body pos="0 0 0">
            <geom name="rbar1" type="capsule" fromto="0 0 0  0.8 0 0.6" />
			<site name="rb1e" pos="0.8 0 0.6"/>
			<joint name="rj1"/>
            <body name="rbar2" pos="0.8 0 0.6">
                <geom name="rbar2" type="capsule" fromto="0 0 0  -0.8 0 0.6"/>
                <joint name="rj2"/>
                <body pos="-0.8 0 0.6">
					<geom name="rbar4" type="capsule" fromto="0 0 0  0.8 0 0.6"/>
					<joint name="rj4"/>
					<site name="rb4e" pos="0.8 0 0.6"/>
                    <body name="rbar5" pos="0.8 0 0.6">
                        <geom name="rbar5" type="capsule" fromto="0 0 0  -0.8 0 0.6"/>
                        <joint name="rj5"/>
                    </body>
				</body>
            </body>
        </body>
        <body pos="0 0 0">
			<geom name="floor" pos="0 0 0" size="0 0 1" type="plane" material="grid"/>
			<site name="f1" pos="-3 0 0"/>
			<site name="f3" pos="3 0 0"/>
			<site name="target" pos="-0.3 0 2.7" size="0.08" rgba="1 0 0 .3"/>
		</body>
    </worldbody>
	
	<equality>
		<connect active="true" name='top' body1='lbar5' body2='rbar5' anchor='0.8 0 0.6'/>
        <connect active="true" name='bottom' body1='lbar2' body2='rbar2' anchor='0.8 0 0.6'/>
	</equality>

    <tendon>
        <spatial name="S1">
            <site site="f2"/>
            <site site="lb2e"/>
        </spatial>
		<spatial name="S2">
            <site site="lb1e"/>
            <site site="rb1e"/>
        </spatial>
		<spatial name="S3">
            <site site="lb2e"/>
            <site site="lb5e"/>
        </spatial>
		<spatial name="S4">
            <site site="rb4e"/>
            <site site="lb4e"/>
        </spatial>
        
        <spatial name="S5">
            <site site="f2"/>
            <site site="lb3e"/>
        </spatial>
        <spatial name="S6">
            <site site="f2"/>
            <site site="rb3e"/>
        </spatial>
        <spatial name="S7">
            <site site="f1"/>
            <site site="lb3e"/>
        </spatial>
        <spatial name="S8">
            <site site="f3"/>
            <site site="rb3e"/>
        </spatial>
        <spatial name="S9">
            <site site="lb5e"/>
            <site site="lb3e"/>
        </spatial>
        <spatial name="S10">
            <site site="lb5e"/>
            <site site="rb3e"/>
        </spatial>
    </tendon>   

    <actuator>
        <motor tendon="S1"/>
        <motor tendon="S2"/>
		<motor tendon="S3"/>
        <motor tendon="S4"/>
        <motor tendon="S5"/>
        <motor tendon="S6"/>
		<motor tendon="S7"/>
        <motor tendon="S8"/>
        <motor tendon="S9"/>
        <motor tendon="S10"/>
    </actuator>
	
	<sensor>
		<framelinvel objtype="site" objname="f2"/>
		<framelinvel objtype="site" objname="lb1e"/>
		<framelinvel objtype="site" objname="lb2e"/>
		<framelinvel objtype="site" objname="lb3e"/>
		<framelinvel objtype="site" objname="lb4e"/>
		<framelinvel objtype="site" objname="lb5e"/>
		<framelinvel objtype="site" objname="rb3e"/>
		<framelinvel objtype="site" objname="rb1e"/>
		<framelinvel objtype="site" objname="rb4e"/>
		<framelinvel objtype="site" objname="f1"/>
		<framelinvel objtype="site" objname="f3"/>
	</sensor>
</mujoco>
